Workbook

Sheet RAW Restaurant Brands Dataset
A1: Brand Name | B1: Annualized Trips | C1: Active Locations | D1: Total Locations | E1: % Franchised | F1: Avg. Basket Size | G1: Marketplace Fee | H1: %Orders from First Time Eaters | I1: Order Defect Rate | J1: Avg. Courier Wait Time (min)
A2: Original Tommy's Hamburgers | B2: 1068012 | C2: 482 | D2: 753 | E2: 0.69 | F2: 16.8 | G2: 0.25 | H2: 0.0468 | I2: 0.028940039 | J2: 7
A3: Baja Fresh Mexican Grill | B3: 1018080 | C3: 556 | D3: 783 | E3: 0.96 | F3: 18.5 | G3: 0.17 | H3: 0.0652 | I3: 0.027053132 | J3: 4
A4: Little Greek | B4: 775008 | C4: 388 | D4: 668 | E4: 0.23 | F4: 22.4 | G4: 0.3 | H4: 0.0736 | I4: 0.029747822 | J4: 45
A5: Tocaya Organica | B5: 264384 | C5: 299 | D5: 320 | E5: 0.56 | F5: 26 | G5: 0.28 | H5: 0.048 | I5: 0.029179748 | J5: 21
A6: Freshii | B6: 238560 | C6: 82 | D6: 191 | E6: 0.22 | F6: 21.7 | G6: 0.25 | H6: 0.0452 | I6: 0.017983438 | J6: 5
A7: Carl's Jr. Restaurants | B7: 226872 | C7: 53 | D7: 58 | E7: 0.76 | F7: 16.6 | G7: 0.26 | H7: 0.0412 | I7: 0.016135534 | J7: 5
A8: Pita Pit | B8: 224136 | C8: 42 | D8: 86 | E8: 0.27 | F8: 16 | G8: 0.3 | H8: 0.07 | I8: 0.016712727 | J8: 14
A9: Cici's Enterprises | B9: 221760 | C9: 72 | D9: 300 | E9: 0.37 | F9: 15.1 | G9: 0.24 | H9: 0.0604 | I9: 0.014803598 | J9: 28
A10: Gus's World Famous Fried Chicken | B10: 216372 | C10: 93 | D10: 930 | E10: 0.55 | F10: 19.8 | G10: 0.26 | H10: 0.0892 | I10: 0.014041635 | J10: 13
A11: The Buffalo Spot | B11: 215280 | C11: 41 | D11: 216 | E11: 0.93 | F11: 17.4 | G11: 0.25 | H11: 0.0756 | I11: 0.014341467 | J11: 37
A12: Wings Over | B12: 211200 | C12: 38 | D12: 46 | E12: 0.68 | F12: 21.4 | G12: 0.24 | H12: 0.0336 | I12: 0.013798989 | J12: 3
A13: Bed-Stuy Fish Fry | B13: 209760 | C13: 98 | D13: 184 | E13: 0.59 | F13: 25.4 | G13: 0.3 | H13: 0.0868 | I13: 0.031642305 | J13: 34
... A201: Chickie's & Pete's | B201: 2592 | C201: 6 | D201: 38 | E201: 0.39 | F201: 28.3 | G201: 0.26 | H201: 0.092 | I201: 0.013036725 | J201: 6

Sheet RAW Demographic Data
A1: Total Population | B1: 8.7 million
A3: Age Demographics: | B3: Age | C3: %
A4: 0 - 17: 23% | B4: =IFERROR(__xludf.DUMMYFUNCTION("split(A4,"":"")"),"0 - 17") -> 0 - 17 | C4: =IFERROR(__xludf.DUMMYFUNCTION("""COMPUTED_VALUE"""),0.23) -> 0.23
A5: 18 - 24: 15% | B5: =IFERROR(__xludf.DUMMYFUNCTION("split(A5,"":"")"),"18 - 24") -> 18 - 24 | C5: =IFERROR(__xludf.DUMMYFUNCTION("""COMPUTED_VALUE"""),0.15) -> 0.15
A6: 25 - 34: 33% | B6: =IFERROR(__xludf.DUMMYFUNCTION("split(A6,"":"")"),"25 - 34") -> 25 - 34 | C6: =IFERROR(__xludf.DUMMYFUNCTION("""COMPUTED_VALUE"""),0.33) -> 0.33
A7: 35 - 64: 19% | B7: =IFERROR(__xludf.DUMMYFUNCTION("split(A7,"":"")"),"35 - 64") -> 35 - 64 | C7: =IFERROR(__xludf.DUMMYFUNCTION("""COMPUTED_VALUE"""),0.19) -> 0.19
A8: 65+: 10% | B8: =IFERROR(__xludf.DUMMYFUNCTION("split(A8,"":"")"),"65+") -> 65+ | C8: =IFERROR(__xludf.DUMMYFUNCTION("""COMPUTED_VALUE"""),0.1) -> 0.1
A10: Occupation Demographics: | B10: Occupation | C10: %
A11: Children (U18): 23% | B11: =IFERROR(__xludf.DUMMYFUNCTION("split(A11,"":"")"),"Children (U18)") -> Children (U18) | C11: =IFERROR(__xludf.DUMMYFUNCTION("""COMPUTED_VALUE"""),0.23) -> 0.23
A12: Post-Secondary Students: 18% | B12: =IFERROR(__xludf.DUMMYFUNCTION("split(A12,"":"")"),"Post-Secondary Students") -> Post-Secondary Students | C12: =IFERROR(__xludf.DUMMYFUNCTION("""COMPUTED_VALUE"""),0.18) -> 0.18
A13: Employed (Full Time): 30% | B13: =IFERROR(__xludf.DUMMYFUNCTION("split(A13,"":"")"),"Employed (Full Time)") -> Employed (Full Time) | C13: =IFERROR(__xludf.DUMMYFUNCTION("""COMPUTED_VALUE"""),0.3) -> 0.3
A14: Employed (Part Time): 16% | B14: =IFERROR(__xludf.DUMMYFUNCTION("split(A14,"":"")"),"Employed (Part Time)") -> Employed (Part Time) | C14: =IFERROR(__xludf.DUMMYFUNCTION("""COMPUTED_VALUE"""),0.16) -> 0.16
A15: Unemployed / Stay-at-Home Parents: 5% | B15: =IFERROR(__xludf.DUMMYFUNCTION("split(A15,"":"")"),"Unemployed / Stay-at-Home Parents") -> Unemployed / Stay-at-Home Parents | C15: =IFERROR(__xludf.DUMMYFUNCTION("""COMPUTED_VALUE"""),0.05) -> 0.05
A16: Retired: 8% | B16: =IFERROR(__xludf.DUMMYFUNCTION("split(A16,"":"")"),"Retired") -> Retired | C16: =IFERROR(__xludf.DUMMYFUNCTION("""COMPUTED_VALUE"""),0.08) -> 0.08
A18: Suburban / Urban (% of population) | B18: Suburban / Urban | C18: %
A19: Suburban 39%: | B19: Suburban | C19: 0.39
A20: Urban 61%: | B20: Urban | C20: 0.61
A22: Market Share of Online Food Delivery (% of Orders) | B22: Market Share of Online Food Delivery | C22: %
A23: Uber Eats: 18% | B23: =IFERROR(__xludf.DUMMYFUNCTION("split(A23,"":"")"),"Uber Eats") -> Uber Eats | C23: =IFERROR(__xludf.DUMMYFUNCTION("""COMPUTED_VALUE"""),0.18) -> 0.18
A24: Competitor: 82% | B24: =IFERROR(__xludf.DUMMYFUNCTION("split(A24,"":"")"),"Competitor") -> Competitor | C24: =IFERROR(__xludf.DUMMYFUNCTION("""COMPUTED_VALUE"""),0.82) -> 0.82
A26: Time in Market: | B26: Company | C26: Time
A27: Uber Eats: 6 months | B27: =IFERROR(__xludf.DUMMYFUNCTION("split(A27,"":"")"),"Uber Eats") -> Uber Eats | C27: =IFERROR(__xludf.DUMMYFUNCTION("""COMPUTED_VALUE""")," 6 months") -> 6 months
A28: Competitor: 24 Months | B28: =IFERROR(__xludf.DUMMYFUNCTION("split(A28,"":"")"),"Competitor") -> Competitor | C28: =IFERROR(__xludf.DUMMYFUNCTION("""COMPUTED_VALUE""")," 24 Months") -> 24 Months

Sheet Input Resturant Brands Scoring 
A1: Scoring Model | B1: Points | C1: Formula | D1: Logic
A2: Total Points | B2: 100 | C2: Volume + Ops + Economis = Total Score
A3: Volume | B3: 35 | C3: PercentRank * Points | D3: High Volume indicates higher opportunity
A4: Operational Quality | B4: =sum(B5:B6) -> 30 | C4: Wait Time Score + Defect Score
A5: Wait Time | B5: 18 | C5: 1-PercentRank * Points | D5: Lower Wait Time means better operational quality
A6: Defect | B6: 12 | C6: 1-PercentRank * Points | D6: Lower Defect Rate means better operational quality
A7: Economics | B7: 35 | C7: PercentRank * Points | D7: Higher Basket * Fee results in more revenue

Sheet Input Fee and Elasticity Inputs
A1: Fee Inputs | B1: Fee Change (Default) (Min 10% Max 30%) | C1: Logic
A2: S-tier volume lift | B2: -0.02 | C2: Reward top preformers, grow them
A3: A-tier volume lift | B3: -0.005 | C3: slight incentive to maintain quality
A4: B-tier volume loss | B4: 0.02 | C4: pay more or improve to move up
A5: C-tier volume loss | B5: 0.03 | C5: Extract value or exit (capped at 30%)
A8: Volume Lift | C8: Logic
A9: S-tier volume lift | B9: 0.2 | C9: Feed Optimization top placement drives orders
A10: A-tier volume lift | B10: 0.1 | C10: Feed Optimization top placement better placement than current on average
A11: B-tier volume loss | B11: -0.05 | C11: Feed deprioritization + merchant pushback
A12: C-tier volume loss | B12: -0.15 | C12: Feed deprioritization + some churn

Sheet Model Resturant Brands Scoring 
L1: Calculated_JD Merchant Scoring Model | U1: Caluclated_JD Fee Optimization
A2: {='RAW Restaurant Brands Dataset'!A:J} -> Brand Name | B2: Annualized Trips | C2: Active Locations | D2: Total Locations | E2: % Franchised | F2: Avg. Basket Size | G2: Marketplace Fee | H2: %Orders from First Time Eaters | I2: Order Defect Rate | J2: Avg. Courier Wait Time (min) | K2: Type | L2: Rev / Order (Helper) | M2: Volume Score | N2: Wait Time Score | O2: Defect Score | P2: Quality Score Total | Q2: Econ Score | R2: Total Score | S2: Rank | T2: Tier | U2: Current Rev | V2: Target Fee | W2: Fee Change | X2: New Trips | Y2: New Rev / Order | Z2: New Revenue | AA2: Revenue Delta
A3: Original Tommy's Hamburgers | B3: 1068012 | C3: 482 | D3: 753 | E3: 0.69 | F3: 16.8 | G3: 0.25 | H3: 0.0468 | I3: 0.028940039 | J3: 7 | K3: =if(C3>20,"Enterprise","SMB") -> Enterprise | L3: =F3*G3 -> 4.2 | M3: =PERCENTRANK(B$3:B$202,B3)*'Input Resturant Brands Scoring '!$B$3 -> 35 | N3: =(1-PERCENTRANK(J$3:J$202,J3))*'Input Resturant Brands Scoring '!$B$5 -> 12.204 | O3: =(1-PERCENTRANK(I$3:I$202,I3))*'Input Resturant Brands Scoring '!$B$6 -> 1.212 | P3: =sum(N3:O3) -> 13.416 | Q3: =PERCENTRANK(L$3:L$202,L3)*'Input Resturant Brands Scoring '!$B$7 -> 5.285 | R3: =M3+N3+O3+Q3 -> 53.701 | S3: =RANK(R3,R$3:R$202,0) -> 87 | T3: =IF(S3<=10,"S",IF(S3<=50,"A",IF(S3<=150,"B","C"))) -> B | U3: =G3*F3*B3 -> 4485650.4 | V3: =MIN(0.3, MAX(0.1, IF(T3="S", G3-0.02, IF(T3="A", G3-0.005, IF(T3="B", G3+0.02, G3+0.03))))) -> 0.27 | W3: =V3-G3 -> 0.02 | X3: =IF(T3="S", B3*(1+'Input Fee and Elasticity Inputs'!$B$9), IF(T3="A", B3*(1+'Input Fee and Elasticity Inputs'!$B$10), IF(T3="B", B3*(1+'Input Fee and Elasticity Inputs'!$B$11), B3*(1+'Input Fee and Elasticity Inputs'!$B$12)))) -> 1014611.4 | Y3: =F3*V3 -> 4.536 | Z3: =Y3*X3 -> 4602277.3 | AA3: =Z3-U3 -> 116626.91
A4: Baja Fresh Mexican Grill | B4: 1018080 | C4: 556 | D4: 783 | E4: 0.96 | F4: 18.5 | G4: 0.17 | H4: 0.0652 | I4: 0.027053132 | J4: 4 | K4: =if(C4>20,"Enterprise","SMB") -> Enterprise | L4: =F4*G4 -> 3.145 | M4: =PERCENTRANK(B$3:B$202,B4)*'Input Resturant Brands Scoring '!$B$3 -> 34.825 | N4: =(1-PERCENTRANK(J$3:J$202,J4))*'Input Resturant Brands Scoring '!$B$5 -> 17.1 | O4: =(1-PERCENTRANK(I$3:I$202,I4))*'Input Resturant Brands Scoring '!$B$6 -> 1.872 | P4: =sum(N4:O4) -> 18.972 | Q4: =PERCENTRANK(L$3:L$202,L4)*'Input Resturant Brands Scoring '!$B$7 -> 0.7 | R4: =M4+N4+O4+Q4 -> 54.497 | S4: =RANK(R4,R$3:R$202,0) -> 82 | T4: =IF(S4<=10,"S",IF(S4<=50,"A",IF(S4<=150,"B","C"))) -> B | U4: =G4*F4*B4 -> 3201861.6 | V4: =MIN(0.3, MAX(0.1, IF(T4="S", G4-0.02, IF(T4="A", G4-0.005, IF(T4="B", G4+0.02, G4+0.03))))) -> 0.19 | W4: =V4-G4 -> 0.02 | X4: =IF(T4="S", B4*(1+'Input Fee and Elasticity Inputs'!$B$9), IF(T4="A", B4*(1+'Input Fee and Elasticity Inputs'!$B$10), IF(T4="B", B4*(1+'Input Fee and Elasticity Inputs'!$B$11), B4*(1+'Input Fee and Elasticity Inputs'!$B$12)))) -> 967176 | Y4: =F4*V4 -> 3.515 | Z4: =Y4*X4 -> 3399623.6 | AA4: =Z4-U4 -> 197762.04
A5: Little Greek | B5: 775008 | C5: 388 | D5: 668 | E5: 0.23 | F5: 22.4 | G5: 0.3 | H5: 0.0736 | I5: 0.029747822 | J5: 45 | K5: =if(C5>20,"Enterprise","SMB") -> Enterprise | L5: =F5*G5 -> 6.72 | M5: =PERCENTRANK(B$3:B$202,B5)*'Input Resturant Brands Scoring '!$B$3 -> 34.65 | N5: =(1-PERCENTRANK(J$3:J$202,J5))*'Input Resturant Brands Scoring '!$B$5 -> 0.27 | O5: =(1-PERCENTRANK(I$3:I$202,I5))*'Input Resturant Brands Scoring '!$B$6 -> 0.9 | P5: =sum(N5:O5) -> 1.17 | Q5: =PERCENTRANK(L$3:L$202,L5)*'Input Resturant Brands Scoring '!$B$7 -> 27.615 | R5: =M5+N5+O5+Q5 -> 63.435 | S5: =RANK(R5,R$3:R$202,0) -> 42 | T5: =IF(S5<=10,"S",IF(S5<=50,"A",IF(S5<=150,"B","C"))) -> A | U5: =G5*F5*B5 -> 5208053.8 | V5: =MIN(0.3, MAX(0.1, IF(T5="S", G5-0.02, IF(T5="A", G5-0.005, IF(T5="B", G5+0.02, G5+0.03))))) -> 0.295 | W5: =V5-G5 -> -0.005 | X5: =IF(T5="S", B5*(1+'Input Fee and Elasticity Inputs'!$B$9), IF(T5="A", B5*(1+'Input Fee and Elasticity Inputs'!$B$10), IF(T5="B", B5*(1+'Input Fee and Elasticity Inputs'!$B$11), B5*(1+'Input Fee and Elasticity Inputs'!$B$12)))) -> 852508.8 | Y5: =F5*V5 -> 6.608 | Z5: =Y5*X5 -> 5633378.2 | AA5: =Z5-U5 -> 425324.39
A6: Tocaya Organica | B6: 264384 | C6: 299 | D6: 320 | E6: 0.56 | F6: 26 | G6: 0.28 | H6: 0.048 | I6: 0.029179748 | J6: 21 | K6: =if(C6>20,"Enterprise","SMB") -> Enterprise | L6: =F6*G6 -> 7.28 | M6: =PERCENTRANK(B$3:B$202,B6)*'Input Resturant Brands Scoring '!$B$3 -> 34.475 | N6: =(1-PERCENTRANK(J$3:J$202,J6))*'Input Resturant Brands Scoring '!$B$5 -> 3.348 | O6: =(1-PERCENTRANK(I$3:I$202,I6))*'Input Resturant Brands Scoring '!$B$6 -> 1.02 | P6: =sum(N6:O6) -> 4.368 | Q6: =PERCENTRANK(L$3:L$202,L6)*'Input Resturant Brands Scoring '!$B$7 -> 30.065 | R6: =M6+N6+O6+Q6 -> 68.908 | S6: =RANK(R6,R$3:R$202,0) -> 23 | T6: =IF(S6<=10,"S",IF(S6<=50,"A",IF(S6<=150,"B","C"))) -> A | U6: =G6*F6*B6 -> 1924715.5 | V6: =MIN(0.3, MAX(0.1, IF(T6="S", G6-0.02, IF(T6="A", G6-0.005, IF(T6="B", G6+0.02, G6+0.03))))) -> 0.275 | W6: =V6-G6 -> -0.005 | X6: =IF(T6="S", B6*(1+'Input Fee and Elasticity Inputs'!$B$9), IF(T6="A", B6*(1+'Input Fee and Elasticity Inputs'!$B$10), IF(T6="B", B6*(1+'Input Fee and Elasticity Inputs'!$B$11), B6*(1+'Input Fee and Elasticity Inputs'!$B$12)))) -> 290822.4 | Y6: =F6*V6 -> 7.15 | Z6: =Y6*X6 -> 2079380.2 | AA6: =Z6-U6 -> 154664.64
A7: Freshii | B7: 238560 | C7: 82 | D7: 191 | E7: 0.22 | F7: 21.7 | G7: 0.25 | H7: 0.0452 | I7: 0.017983438 | J7: 5 | K7: =if(C7>20,"Enterprise","SMB") -> Enterprise | L7: =F7*G7 -> 5.425 | M7: =PERCENTRANK(B$3:B$202,B7)*'Input Resturant Brands Scoring '!$B$3 -> 34.3 | N7: =(1-PERCENTRANK(J$3:J$202,J7))*'Input Resturant Brands Scoring '!$B$5 -> 15.462 | O7: =(1-PERCENTRANK(I$3:I$202,I7))*'Input Resturant Brands Scoring '!$B$6 -> 6.216 | P7: =sum(N7:O7) -> 21.678 | Q7: =PERCENTRANK(L$3:L$202,L7)*'Input Resturant Brands Scoring '!$B$7 -> 17.78 | R7: =M7+N7+O7+Q7 -> 73.758 | S7: =RANK(R7,R$3:R$202,0) -> 9 | T7: =IF(S7<=10,"S",IF(S7<=50,"A",IF(S7<=150,"B","C"))) -> S | U7: =G7*F7*B7 -> 1294188 | V7: =MIN(0.3, MAX(0.1, IF(T7="S", G7-0.02, IF(T7="A", G7-0.005, IF(T7="B", G7+0.02, G7+0.03))))) -> 0.23 | W7: =V7-G7 -> -0.02 | X7: =IF(T7="S", B7*(1+'Input Fee and Elasticity Inputs'!$B$9), IF(T7="A", B7*(1+'Input Fee and Elasticity Inputs'!$B$10), IF(T7="B", B7*(1+'Input Fee and Elasticity Inputs'!$B$11), B7*(1+'Input Fee and Elasticity Inputs'!$B$12)))) -> 286272 | Y7: =F7*V7 -> 4.991 | Z7: =Y7*X7 -> 1428783.6 | AA7: =Z7-U7 -> 134595.55
A8: Carl's Jr. Restaurants | B8: 226872 | C8: 53 | D8: 58 | E8: 0.76 | F8: 16.6 | G8: 0.26 | H8: 0.0412 | I8: 0.016135534 | J8: 5 | K8: =if(C8>20,"Enterprise","SMB") -> Enterprise | L8: =F8*G8 -> 4.316 | M8: =PERCENTRANK(B$3:B$202,B8)*'Input Resturant Brands Scoring '!$B$3 -> 34.125 | N8: =(1-PERCENTRANK(J$3:J$202,J8))*'Input Resturant Brands Scoring '!$B$5 -> 15.462 | O8: =(1-PERCENTRANK(I$3:I$202,I8))*'Input Resturant Brands Scoring '!$B$6 -> 7.896 | P8: =sum(N8:O8) -> 23.358 | Q8: =PERCENTRANK(L$3:L$202,L8)*'Input Resturant Brands Scoring '!$B$7 -> 5.81 | R8: =M8+N8+O8+Q8 -> 63.293 | S8: =RANK(R8,R$3:R$202,0) -> 44 | T8: =IF(S8<=10,"S",IF(S8<=50,"A",IF(S8<=150,"B","C"))) -> A | U8: =G8*F8*B8 -> 979179.55 | V8: =MIN(0.3, MAX(0.1, IF(T8="S", G8-0.02, IF(T8="A", G8-0.005, IF(T8="B", G8+0.02, G8+0.03))))) -> 0.255 | W8: =V8-G8 -> -0.005 | X8: =IF(T8="S", B8*(1+'Input Fee and Elasticity Inputs'!$B$9), IF(T8="A", B8*(1+'Input Fee and Elasticity Inputs'!$B$10), IF(T8="B", B8*(1+'Input Fee and Elasticity Inputs'!$B$11), B8*(1+'Input Fee and Elasticity Inputs'!$B$12)))) -> 249559.2 | Y8: =F8*V8 -> 4.233 | Z8: =Y8*X8 -> 1056384.1 | AA8: =Z8-U8 -> 77204.542
A9: Pita Pit | B9: 224136 | C9: 42 | D9: 86 | E9: 0.27 | F9: 16 | G9: 0.3 | H9: 0.07 | I9: 0.016712727 | J9: 14 | K9: =if(C9>20,"Enterprise","SMB") -> Enterprise | L9: =F9*G9 -> 4.8 | M9: =PERCENTRANK(B$3:B$202,B9)*'Input Resturant Brands Scoring '!$B$3 -> 33.95 | N9: =(1-PERCENTRANK(J$3:J$202,J9))*'Input Resturant Brands Scoring '!$B$5 -> 6.426 | O9: =(1-PERCENTRANK(I$3:I$202,I9))*'Input Resturant Brands Scoring '!$B$6 -> 7.236 | P9: =sum(N9:O9) -> 13.662 | Q9: =PERCENTRANK(L$3:L$202,L9)*'Input Resturant Brands Scoring '!$B$7 -> 10.745 | R9: =M9+N9+O9+Q9 -> 58.357 | S9: =RANK(R9,R$3:R$202,0) -> 60 | T9: =IF(S9<=10,"S",IF(S9<=50,"A",IF(S9<=150,"B","C"))) -> B | U9: =G9*F9*B9 -> 1075852.8 | V9: =MIN(0.3, MAX(0.1, IF(T9="S", G9-0.02, IF(T9="A", G9-0.005, IF(T9="B", G9+0.02, G9+0.03))))) -> 0.3 | W9: =V9-G9 -> 0 | X9: =IF(T9="S", B9*(1+'Input Fee and Elasticity Inputs'!$B$9), IF(T9="A", B9*(1+'Input Fee and Elasticity Inputs'!$B$10), IF(T9="B", B9*(1+'Input Fee and Elasticity Inputs'!$B$11), B9*(1+'Input Fee and Elasticity Inputs'!$B$12)))) -> 212929.2 | Y9: =F9*V9 -> 4.8 | Z9: =Y9*X9 -> 1022060.2 | AA9: =Z9-U9 -> -53792.64
A10: Cici's Enterprises | B10: 221760 | C10: 72 | D10: 300 | E10: 0.37 | F10: 15.1 | G10: 0.24 | H10: 0.0604 | I10: 0.014803598 | J10: 28 | K10: =if(C10>20,"Enterprise","SMB") -> Enterprise | L10: =F10*G10 -> 3.624 | M10: =PERCENTRANK(B$3:B$202,B10)*'Input Resturant Brands Scoring '!$B$3 -> 33.775 | N10: =(1-PERCENTRANK(J$3:J$202,J10))*'Input Resturant Brands Scoring '!$B$5 -> 1.62 | O10: =(1-PERCENTRANK(I$3:I$202,I10))*'Input Resturant Brands Scoring '!$B$6 -> 8.808 | P10: =sum(N10:O10) -> 10.428 | Q10: =PERCENTRANK(L$3:L$202,L10)*'Input Resturant Brands Scoring '!$B$7 -> 1.75 | R10: =M10+N10+O10+Q10 -> 45.953 | S10: =RANK(R10,R$3:R$202,0) -> 130 | T10: =IF(S10<=10,"S",IF(S10<=50,"A",IF(S10<=150,"B","C"))) -> B | U10: =G10*F10*B10 -> 803658.24 | V10: =MIN(0.3, MAX(0.1, IF(T10="S", G10-0.02, IF(T10="A", G10-0.005, IF(T10="B", G10+0.02, G10+0.03))))) -> 0.26 | W10: =V10-G10 -> 0.02 | X10: =IF(T10="S", B10*(1+'Input Fee and Elasticity Inputs'!$B$9), IF(T10="A", B10*(1+'Input Fee and Elasticity Inputs'!$B$10), IF(T10="B", B10*(1+'Input Fee and Elasticity Inputs'!$B$11), B10*(1+'Input Fee and Elasticity Inputs'!$B$12)))) -> 210672 | Y10: =F10*V10 -> 3.926 | Z10: =Y10*X10 -> 827098.27 | AA10: =Z10-U10 -> 23440.032
A11: Gus's World Famous Fried Chicken | B11: 216372 | C11: 93 | D11: 930 | E11: 0.55 | F11: 19.8 | G11: 0.26 | H11: 0.0892 | I11: 0.014041635 | J11: 13 | K11: =if(C11>20,"Enterprise","SMB") -> Enterprise | L11: =F11*G11 -> 5.148 | M11: =PERCENTRANK(B$3:B$202,B11)*'Input Resturant Brands Scoring '!$B$3 -> 33.6 | N11: =(1-PERCENTRANK(J$3:J$202,J11))*'Input Resturant Brands Scoring '!$B$5 -> 7.056 | O11: =(1-PERCENTRANK(I$3:I$202,I11))*'Input Resturant Brands Scoring '!$B$6 -> 9.948 | P11: =sum(N11:O11) -> 17.004 | Q11: =PERCENTRANK(L$3:L$202,L11)*'Input Resturant Brands Scoring '!$B$7 -> 14.595 | R11: =M11+N11+O11+Q11 -> 65.199 | S11: =RANK(R11,R$3:R$202,0) -> 35 | T11: =IF(S11<=10,"S",IF(S11<=50,"A",IF(S11<=150,"B","C"))) -> A | U11: =G11*F11*B11 -> 1113883.1 | V11: =MIN(0.3, MAX(0.1, IF(T11="S", G11-0.02, IF(T11="A", G11-0.005, IF(T11="B", G11+0.02, G11+0.03))))) -> 0.255 | W11: =V11-G11 -> -0.005 | X11: =IF(T11="S", B11*(1+'Input Fee and Elasticity Inputs'!$B$9), IF(T11="A", B11*(1+'Input Fee and Elasticity Inputs'!$B$10), IF(T11="B", B11*(1+'Input Fee and Elasticity Inputs'!$B$11), B11*(1+'Input Fee and Elasticity Inputs'!$B$12)))) -> 238009.2 | Y11: =F11*V11 -> 5.049 | Z11: =Y11*X11 -> 1201708.5 | AA11: =Z11-U11 -> 87825.395
A12: The Buffalo Spot | B12: 215280 | C12: 41 | D12: 216 | E12: 0.93 | F12: 17.4 | G12: 0.25 | H12: 0.0756 | I12: 0.014341467 | J12: 37 | K12: =if(C12>20,"Enterprise","SMB") -> Enterprise | L12: =F12*G12 -> 4.35 | M12: =PERCENTRANK(B$3:B$202,B12)*'Input Resturant Brands Scoring '!$B$3 -> 33.425 | N12: =(1-PERCENTRANK(J$3:J$202,J12))*'Input Resturant Brands Scoring '!$B$5 -> 0.81 | O12: =(1-PERCENTRANK(I$3:I$202,I12))*'Input Resturant Brands Scoring '!$B$6 -> 9.288 | P12: =sum(N12:O12) -> 10.098 | Q12: =PERCENTRANK(L$3:L$202,L12)*'Input Resturant Brands Scoring '!$B$7 -> 6.51 | R12: =M12+N12+O12+Q12 -> 50.033 | S12: =RANK(R12,R$3:R$202,0) -> 107 | T12: =IF(S12<=10,"S",IF(S12<=50,"A",IF(S12<=150,"B","C"))) -> B | U12: =G12*F12*B12 -> 936468 | V12: =MIN(0.3, MAX(0.1, IF(T12="S", G12-0.02, IF(T12="A", G12-0.005, IF(T12="B", G12+0.02, G12+0.03))))) -> 0.27 | W12: =V12-G12 -> 0.02 | X12: =IF(T12="S", B12*(1+'Input Fee and Elasticity Inputs'!$B$9), IF(T12="A", B12*(1+'Input Fee and Elasticity Inputs'!$B$10), IF(T12="B", B12*(1+'Input Fee and Elasticity Inputs'!$B$11), B12*(1+'Input Fee and Elasticity Inputs'!$B$12)))) -> 204516 | Y12: =F12*V12 -> 4.698 | Z12: =Y12*X12 -> 960816.17 | AA12: =Z12-U12 -> 24348.168
A13: Wings Over | B13: 211200 | C13: 38 | D13: 46 | E13: 0.68 | F13: 21.4 | G13: 0.24 | H13: 0.0336 | I13: 0.013798989 | J13: 3 | K13: =if(C13>20,"Enterprise","SMB") -> Enterprise | L13: =F13*G13 -> 5.136 | M13: =PERCENTRANK(B$3:B$202,B13)*'Input Resturant Brands Scoring '!$B$3 -> 33.25 | N13: =(1-PERCENTRANK(J$3:J$202,J13))*'Input Resturant Brands Scoring '!$B$5 -> 18 | O13: =(1-PERCENTRANK(I$3:I$202,I13))*'Input Resturant Brands Scoring '!$B$6 -> 10.188 | P13: =sum(N13:O13) -> 28.188 | Q13: =PERCENTRANK(L$3:L$202,L13)*'Input Resturant Brands Scoring '!$B$7 -> 14.42 | R13: =M13+N13+O13+Q13 -> 75.858 | S13: =RANK(R13,R$3:R$202,0) -> 7 | T13: =IF(S13<=10,"S",IF(S13<=50,"A",IF(S13<=150,"B","C"))) -> S | U13: =G13*F13*B13 -> 1084723.2 | V13: =MIN(0.3, MAX(0.1, IF(T13="S", G13-0.02, IF(T13="A", G13-0.005, IF(T13="B", G13+0.02, G13+0.03))))) -> 0.22 | W13: =V13-G13 -> -0.02 | X13: =IF(T13="S", B13*(1+'Input Fee and Elasticity Inputs'!$B$9), IF(T13="A", B13*(1+'Input Fee and Elasticity Inputs'!$B$10), IF(T13="B", B13*(1+'Input Fee and Elasticity Inputs'!$B$11), B13*(1+'Input Fee and Elasticity Inputs'!$B$12)))) -> 253440 | Y13: =F13*V13 -> 4.708 | Z13: =Y13*X13 -> 1193195.5 | AA13: =Z13-U13 -> 108472.32
A14: Bed-Stuy Fish Fry | B14: 209760 | C14: 98 | D14: 184 | E14: 0.59 | F14: 25.4 | G14: 0.3 | H14: 0.0868 | I14: 0.031642305 | J14: 34 | K14: =if(C14>20,"Enterprise","SMB") -> Enterprise | L14: =F14*G14 -> 7.62 | M14: =PERCENTRANK(B$3:B$202,B14)*'Input Resturant Brands Scoring '!$B$3 -> 33.075 | N14: =(1-PERCENTRANK(J$3:J$202,J14))*'Input Resturant Brands Scoring '!$B$5 -> 1.08 | O14: =(1-PERCENTRANK(I$3:I$202,I14))*'Input Resturant Brands Scoring '!$B$6 -> 0.48 | P14: =sum(N14:O14) -> 1.56 | Q14: =PERCENTRANK(L$3:L$202,L14)*'Input Resturant Brands Scoring '!$B$7 -> 31.85 | R14: =M14+N14+O14+Q14 -> 66.485 | S14: =RANK(R14,R$3:R$202,0) -> 31 | T14: =IF(S14<=10,"S",IF(S14<=50,"A",IF(S14<=150,"B","C"))) -> A | U14: =G14*F14*B14 -> 1598371.2 | V14: =MIN(0.3, MAX(0.1, IF(T14="S", G14-0.02, IF(T14="A", G14-0.005, IF(T14="B", G14+0.02, G14+0.03))))) -> 0.295 | W14: =V14-G14 -> -0.005 | X14: =IF(T14="S", B14*(1+'Input Fee and Elasticity Inputs'!$B$9), IF(T14="A", B14*(1+'Input Fee and Elasticity Inputs'!$B$10), IF(T14="B", B14*(1+'Input Fee and Elasticity Inputs'!$B$11), B14*(1+'Input Fee and Elasticity Inputs'!$B$12)))) -> 230736 | Y14: =F14*V14 -> 7.493 | Z14: =Y14*X14 -> 1728904.8 | AA14: =Z14-U14 -> 130533.65
A15: Shari's Cafe & Pies | B15: 209088 | C15: 42 | D15: 86 | E15: 0.99 | F15: 20.6 | G15: 0.29 | H15: 0.0368 | I15: 0.034377076 | J15: 10 | K15: =if(C15>20,"Enterprise","SMB") -> Enterprise | L15: =F15*G15 -> 5.974 | M15: =PERCENTRANK(B$3:B$202,B15)*'Input Resturant Brands Scoring '!$B$3 -> 32.9 | N15: =(1-PERCENTRANK(J$3:J$202,J15))*'Input Resturant Brands Scoring '!$B$5 -> 9.054 | O15: =(1-PERCENTRANK(I$3:I$202,I15))*'Input Resturant Brands Scoring '!$B$6 -> 0.12 | P15: =sum(N15:O15) -> 9.174 | Q15: =PERCENTRANK(L$3:L$202,L15)*'Input Resturant Brands Scoring '!$B$7 -> 22.855 | R15: =M15+N15+O15+Q15 -> 64.929 | S15: =RANK(R15,R$3:R$202,0) -> 36 | T15: =IF(S15<=25,"S",IF(S15<=50,"A",IF(S15<=150,"B","C"))) -> A | U15: =G15*F15*B15 -> 1249091.7 | V15: =MIN(0.3, MAX(0.1, IF(T15="S", G15-0.02, IF(T15="A", G15-0.005, IF(T15="B", G15+0.02, G15+0.03))))) -> 0.285 | W15: =V15-G15 -> -0.005 | X15: =IF(T15="S", B15*(1+'Input Fee and Elasticity Inputs'!$B$9), IF(T15="A", B15*(1+'Input Fee and Elasticity Inputs'!$B$10), IF(T15="B", B15*(1+'Input Fee and Elasticity Inputs'!$B$11), B15*(1+'Input Fee and Elasticity Inputs'!$B$12)))) -> 229996.8 | Y15: =F15*V15 -> 5.871 | Z15: =Y15*X15 -> 1350311.2 | AA15: =Z15-U15 -> 101219.5
A16: Romano's Macaroni Grill | B16: 209040 | C16: 41 | D16: 103 | E16: 0.28 | F16: 34.4 | G16: 0.25 | H16: 0.1328 | I16: 0.031960196 | J16: 24 | K16: =if(C16>20,"Enterprise","SMB") -> Enterprise | L16: =F16*G16 -> 8.6 | M16: =PERCENTRANK(B$3:B$202,B16)*'Input Resturant Brands Scoring '!$B$3 -> 32.725 | N16: =(1-PERCENTRANK(J$3:J$202,J16))*'Input Resturant Brands Scoring '!$B$5 -> 2.448 | O16: =(1-PERCENTRANK(I$3:I$202,I16))*'Input Resturant Brands Scoring '!$B$6 -> 0.42 | P16: =sum(N16:O16) -> 2.868 | Q16: =PERCENTRANK(L$3:L$202,L16)*'Input Resturant Brands Scoring '!$B$7 -> 33.775 | R16: =M16+N16+O16+Q16 -> 69.368 | S16: =RANK(R16,R$3:R$202,0) -> 21 | T16: =IF(S16<=10,"S",IF(S16<=50,"A",IF(S16<=150,"B","C"))) -> A | U16: =G16*F16*B16 -> 1797744 | V16: =MIN(0.3, MAX(0.1, IF(T16="S", G16-0.02, IF(T16="A", G16-0.005, IF(T16="B", G16+0.02, G16+0.03))))) -> 0.245 | W16: =V16-G16 -> -0.005 | X16: =IF(T16="S", B16*(1+'Input Fee and Elasticity Inputs'!$B$9), IF(T16="A", B16*(1+'Input Fee and Elasticity Inputs'!$B$10), IF(T16="B", B16*(1+'Input Fee and Elasticity Inputs'!$B$11), B16*(1+'Input Fee and Elasticity Inputs'!$B$12)))) -> 229944 | Y16: =F16*V16 -> 8.428 | Z16: =Y16*X16 -> 1937968 | AA16: =Z16-U16 -> 140224.03
A17: Village Inn | B17: 183120 | C17: 65 | D17: 73 | E17: 0.46 | F17: 20.2 | G17: 0.27 | H17: 0.0912 | I17: 0.032994188 | J17: 20 | K17: =if(C17>20,"Enterprise","SMB") -> Enterprise | L17: =F17*G17 -> 5.454 | M17: =PERCENTRANK(B$3:B$202,B17)*'Input Resturant Brands Scoring '!$B$3 -> 32.55 | N17: =(1-PERCENTRANK(J$3:J$202,J17))*'Input Resturant Brands Scoring '!$B$5 -> 3.528 | O17: =(1-PERCENTRANK(I$3:I$202,I17))*'Input Resturant Brands Scoring '!$B$6 -> 0.24 | P17: =sum(N17:O17) -> 3.768 | Q17: =PERCENTRANK(L$3:L$202,L17)*'Input Resturant Brands Scoring '!$B$7 -> 18.305 | R17: =M17+N17+O17+Q17 -> 54.623 | S17: =RANK(R17,R$3:R$202,0) -> 78 | T17: =IF(S17<=10,"S",IF(S17<=50,"A",IF(S17<=150,"B","C"))) -> B | U17: =G17*F17*B17 -> 998736.48 | V17: =MIN(0.3, MAX(0.1, IF(T17="S", G17-0.02, IF(T17="A", G17-0.005, IF(T17="B", G17+0.02, G17+0.03))))) -> 0.29 | W17: =V17-G17 -> 0.02 | X17: =IF(T17="S", B17*(1+'Input Fee and Elasticity Inputs'!$B$9), IF(T17="A", B17*(1+'Input Fee and Elasticity Inputs'!$B$10), IF(T17="B", B17*(1+'Input Fee and Elasticity Inputs'!$B$11), B17*(1+'Input Fee and Elasticity Inputs'!$B$12)))) -> 173964 | Y17: =F17*V17 -> 5.858 | Z17: =Y17*X17 -> 1019081.1 | AA17: =Z17-U17 -> 20344.632
A18: Gong Cha | B18: 173052 | C18: 51 | D18: 204 | E18: 0.84 | F18: 13.7 | G18: 0.3 | H18: 0.0692 | I18: 0.01429629 | J18: 18 | K18: =if(C18>20,"Enterprise","SMB") -> Enterprise | L18: =F18*G18 -> 4.11 | M18: =PERCENTRANK(B$3:B$202,B18)*'Input Resturant Brands Scoring '!$B$3 -> 32.375 | N18: =(1-PERCENTRANK(J$3:J$202,J18))*'Input Resturant Brands Scoring '!$B$5 -> 3.978 | O18: =(1-PERCENTRANK(I$3:I$202,I18))*'Input Resturant Brands Scoring '!$B$6 -> 9.468 | P18: =sum(N18:O18) -> 13.446 | Q18: =PERCENTRANK(L$3:L$202,L18)*'Input Resturant Brands Scoring '!$B$7 -> 4.585 | R18: =M18+N18+O18+Q18 -> 50.406 | S18: =RANK(R18,R$3:R$202,0) -> 102 | T18: =IF(S18<=10,"S",IF(S18<=50,"A",IF(S18<=150,"B","C"))) -> B | U18: =G18*F18*B18 -> 711243.72 | V18: =MIN(0.3, MAX(0.1, IF(T18="S", G18-0.02, IF(T18="A", G18-0.005, IF(T18="B", G18+0.02, G18+0.03))))) -> 0.3 | W18: =V18-G18 -> 0 | X18: =IF(T18="S", B18*(1+'Input Fee and Elasticity Inputs'!$B$9), IF(T18="A", B18*(1+'Input Fee and Elasticity Inputs'!$B$10), IF(T18="B", B18*(1+'Input Fee and Elasticity Inputs'!$B$11), B18*(1+'Input Fee and Elasticity Inputs'!$B$12)))) -> 164399.4 | Y18: =F18*V18 -> 4.11 | Z18: =Y18*X18 -> 675681.53 | AA18: =Z18-U18 -> -35562.186
A19: Papa John's | B19: 170448 | C19: 43 | D19: 74 | E19: 0.49 | F19: 21.6 | G19: 0.3 | H19: 0.09 | I19: 0.023684085 | J19: 25 | K19: =if(C19>20,"Enterprise","SMB") -> Enterprise | L19: =F19*G19 -> 6.48 | M19: =PERCENTRANK(B$3:B$202,B19)*'Input Resturant Brands Scoring '!$B$3 -> 32.2 | N19: =(1-PERCENTRANK(J$3:J$202,J19))*'Input Resturant Brands Scoring '!$B$5 -> 2.358 | O19: =(1-PERCENTRANK(I$3:I$202,I19))*'Input Resturant Brands Scoring '!$B$6 -> 3.252 | P19: =sum(N19:O19) -> 5.61 | Q19: =PERCENTRANK(L$3:L$202,L19)*'Input Resturant Brands Scoring '!$B$7 -> 25.515 | R19: =M19+N19+O19+Q19 -> 63.325 | S19: =RANK(R19,R$3:R$202,0) -> 43 | T19: =IF(S19<=10,"S",IF(S19<=50,"A",IF(S19<=150,"B","C"))) -> A | U19: =G19*F19*B19 -> 1104503 | V19: =MIN(0.3, MAX(0.1, IF(T19="S", G19-0.02, IF(T19="A", G19-0.005, IF(T19="B", G19+0.02, G19+0.03))))) -> 0.295 | W19: =V19-G19 -> -0.005 | X19: =IF(T19="S", B19*(1+'Input Fee and Elasticity Inputs'!$B$9), IF(T19="A", B19*(1+'Input Fee and Elasticity Inputs'!$B$10), IF(T19="B", B19*(1+'Input Fee and Elasticity Inputs'!$B$11), B19*(1+'Input Fee and Elasticity Inputs'!$B$12)))) -> 187492.8 | Y19: =F19*V19 -> 6.372 | Z19: =Y19*X19 -> 1194704.1 | AA19: =Z19-U19 -> 90201.082
A20: Manny & Olga's Pizza | B20: 165396 | C20: 143 | D20: 318 | E20: 0.56 | F20: 21.7 | G20: 0.3 | H20: 0.0512 | I20: 0.024804925 | J20: 17 | K20: =if(C20>20,"Enterprise","SMB") -> Enterprise | L20: =F20*G20 -> 6.51 | M20: =PERCENTRANK(B$3:B$202,B20)*'Input Resturant Brands Scoring '!$B$3 -> 32.025 | N20: =(1-PERCENTRANK(J$3:J$202,J20))*'Input Resturant Brands Scoring '!$B$5 -> 4.608 | O20: =(1-PERCENTRANK(I$3:I$202,I20))*'Input Resturant Brands Scoring '!$B$6 -> 2.532 | P20: =sum(N20:O20) -> 7.14 | Q20: =PERCENTRANK(L$3:L$202,L20)*'Input Resturant Brands Scoring '!$B$7 -> 26.04 | R20: =M20+N20+O20+Q20 -> 65.205 | S20: =RANK(R20,R$3:R$202,0) -> 34 | T20: =IF(S20<=10,"S",IF(S20<=50,"A",IF(S20<=150,"B","C"))) -> A | U20: =G20*F20*B20 -> 1076728 | V20: =MIN(0.3, MAX(0.1, IF(T20="S", G20-0.02, IF(T20="A", G20-0.005, IF(T20="B", G20+0.02, G20+0.03))))) -> 0.295 | W20: =V20-G20 -> -0.005 | X20: =IF(T20="S", B20*(1+'Input Fee and Elasticity Inputs'!$B$9), IF(T20="A", B20*(1+'Input Fee and Elasticity Inputs'!$B$10), IF(T20="B", B20*(1+'Input Fee and Elasticity Inputs'!$B$11), B20*(1+'Input Fee and Elasticity Inputs'!$B$12)))) -> 181935.6 | Y20: =F20*V20 -> 6.4015 | Z20: =Y20*X20 -> 1164660.7 | AA20: =Z20-U20 -> 87932.783
A21: Corporate Management Group | B21: 161568 | C21: 90 | D21: 126 | E21: 0.35 | F21: 22.1 | G21: 0.23 | H21: 0.0864 | I21: 0.023886064 | J21: 5 | K21: =if(C21>20,"Enterprise","SMB") -> Enterprise | L21: =F21*G21 -> 5.083 | M21: =PERCENTRANK(B$3:B$202,B21)*'Input Resturant Brands Scoring '!$B$3 -> 31.85 | N21: =(1-PERCENTRANK(J$3:J$202,J21))*'Input Resturant Brands Scoring '!$B$5 -> 15.462 | O21: =(1-PERCENTRANK(I$3:I$202,I21))*'Input Resturant Brands Scoring '!$B$6 -> 3.072 | P21: =sum(N21:O21) -> 18.534 | Q21: =PERCENTRANK(L$3:L$202,L21)*'Input Resturant Brands Scoring '!$B$7 -> 13.37 | R21: =M21+N21+O21+Q21 -> 63.754 | S21: =RANK(R21,R$3:R$202,0) -> 40 | T21: =IF(S21<=10,"S",IF(S21<=50,"A",IF(S21<=150,"B","C"))) -> A | U21: =G21*F21*B21 -> 821250.14 | V21: =MIN(0.3, MAX(0.1, IF(T21="S", G21-0.02, IF(T21="A", G21-0.005, IF(T21="B", G21+0.02, G21+0.03))))) -> 0.225 | W21: =V21-G21 -> -0.005 | X21: =IF(T21="S", B21*(1+'Input Fee and Elasticity Inputs'!$B$9), IF(T21="A", B21*(1+'Input Fee and Elasticity Inputs'!$B$10), IF(T21="B", B21*(1+'Input Fee and Elasticity Inputs'!$B$11), B21*(1+'Input Fee and Elasticity Inputs'!$B$12)))) -> 177724.8 | Y21: =F21*V21 -> 4.9725 | Z21: =Y21*X21 -> 883736.57 | AA21: =Z21-U21 -> 62486.424
A22: J. Christopher's | B22: 155220 | C22: 40 | D22: 80 | E22: 0.95 | F22: 17.9 | G22: 0.26 | H22: 0.0312 | I22: 0.022966625 | J22: 6 | K22: =if(C22>20,"Enterprise","SMB") -> Enterprise | L22: =F22*G22 -> 4.654 | M22: =PERCENTRANK(B$3:B$202,B22)*'Input Resturant Brands Scoring '!$B$3 -> 31.675 | N22: =(1-PERCENTRANK(J$3:J$202,J22))*'Input Resturant Brands Scoring '!$B$5 -> 14.022 | O22: =(1-PERCENTRANK(I$3:I$202,I22))*'Input Resturant Brands Scoring '!$B$6 -> 3.864 | P22: =sum(N22:O22) -> 17.886 | Q22: =PERCENTRANK(L$3:L$202,L22)*'Input Resturant Brands Scoring '!$B$7 -> 9.485 | R22: =M22+N22+O22+Q22 -> 59.046 | S22: =RANK(R22,R$3:R$202,0) -> 55 | T22: =IF(S22<=10,"S",IF(S22<=50,"A",IF(S22<=150,"B","C"))) -> B | U22: =G22*F22*B22 -> 722393.88 | V22: =MIN(0.3, MAX(0.1, IF(T22="S", G22-0.02, IF(T22="A", G22-0.005, IF(T22="B", G22+0.02, G22+0.03))))) -> 0.28 | W22: =V22-G22 -> 0.02 | X22: =IF(T22="S", B22*(1+'Input Fee and Elasticity Inputs'!$B$9), IF(T22="A", B22*(1+'Input Fee and Elasticity Inputs'!$B$10), IF(T22="B", B22*(1+'Input Fee and Elasticity Inputs'!$B$11), B22*(1+'Input Fee and Elasticity Inputs'!$B$12)))) -> 147459 | Y22: =F22*V22 -> 5.012 | Z22: =Y22*X22 -> 739064.51 | AA22: =Z22-U22 -> 16670.628
A23: First Watch | B23: 149760 | C23: 37 | D23: 58 | E23: 0.28 | F23: 22 | G23: 0.3 | H23: 0.0836 | I23: 0.021695329 | J23: 9 | K23: =if(C23>20,"Enterprise","SMB") -> Enterprise | L23: =F23*G23 -> 6.6 | M23: =PERCENTRANK(B$3:B$202,B23)*'Input Resturant Brands Scoring '!$B$3 -> 31.465 | N23: =(1-PERCENTRANK(J$3:J$202,J23))*'Input Resturant Brands Scoring '!$B$5 -> 10.044 | O23: =(1-PERCENTRANK(I$3:I$202,I23))*'Input Resturant Brands Scoring '!$B$6 -> 4.584 | P23: =sum(N23:O23) -> 14.628 | Q23: =PERCENTRANK(L$3:L$202,L23)*'Input Resturant Brands Scoring '!$B$7 -> 26.39 | R23: =M23+N23+O23+Q23 -> 72.483 | S23: =RANK(R23,R$3:R$202,0) -> 12 | T23: =IF(S23<=10,"S",IF(S23<=50,"A",IF(S23<=150,"B","C"))) -> A | U23: =G23*F23*B23 -> 988416 | V23: =MIN(0.3, MAX(0.1, IF(T23="S", G23-0.02, IF(T23="A", G23-0.005, IF(T23="B", G23+0.02, G23+0.03))))) -> 0.295 | W23: =V23-G23 -> -0.005 | X23: =IF(T23="S", B23*(1+'Input Fee and Elasticity Inputs'!$B$9), IF(T23="A", B23*(1+'Input Fee and Elasticity Inputs'!$B$10), IF(T23="B", B23*(1+'Input Fee and Elasticity Inputs'!$B$11), B23*(1+'Input Fee and Elasticity Inputs'!$B$12)))) -> 164736 | Y23: =F23*V23 -> 6.49 | Z23: =Y23*X23 -> 1069136.6 | AA23: =Z23-U23 -> 80720.64
A24: Fatburger | B24: 148800 | C24: 190 | D24: 1188 | E24: 0.4 | F24: 19.8 | G24: 0.26 | H24: 0.0456 | I24: 0.022888126 | J24: 8 | K24: =if(C24>20,"Enterprise","SMB") -> Enterprise | L24: =F24*G24 -> 5.148 | M24: =PERCENTRANK(B$3:B$202,B24)*'Input Resturant Brands Scoring '!$B$3 -> 31.29 | N24: =(1-PERCENTRANK(J$3:J$202,J24))*'Input Resturant Brands Scoring '!$B$5 -> 11.574 | O24: =(1-PERCENTRANK(I$3:I$202,I24))*'Input Resturant Brands Scoring '!$B$6 -> 3.924 | P24: =sum(N24:O24) -> 15.498 | Q24: =PERCENTRANK(L$3:L$202,L24)*'Input Resturant Brands Scoring '!$B$7 -> 14.595 | R24: =M24+N24+O24+Q24 -> 61.383 | S24: =RANK(R24,R$3:R$202,0) -> 50 | T24: =IF(S24<=10,"S",IF(S24<=50,"A",IF(S24<=150,"B","C"))) -> A | U24: =G24*F24*B24 -> 766022.4 | V24: =MIN(0.3, MAX(0.1, IF(T24="S", G24-0.02, IF(T24="A", G24-0.005, IF(T24="B", G24+0.02, G24+0.03))))) -> 0.255 | W24: =V24-G24 -> -0.005 | X24: =IF(T24="S", B24*(1+'Input Fee and Elasticity Inputs'!$B$9), IF(T24="A", B24*(1+'Input Fee and Elasticity Inputs'!$B$10), IF(T24="B", B24*(1+'Input Fee and Elasticity Inputs'!$B$11), B24*(1+'Input Fee and Elasticity Inputs'!$B$12)))) -> 163680 | Y24: =F24*V24 -> 5.049 | Z24: =Y24*X24 -> 826420.32 | AA24: =Z24-U24 -> 60397.92
A25: JINYA Ramen Bar | B25: 145392 | C25: 27 | D25: 34 | E25: 0.34 | F25: 26.4 | G25: 0.26 | H25: 0.0848 | I25: 0.023045459 | J25: 9 | K25: =if(C25>20,"Enterprise","SMB") -> Enterprise | L25: =F25*G25 -> 6.864 | M25: =PERCENTRANK(B$3:B$202,B25)*'Input Resturant Brands Scoring '!$B$3 -> 31.115 | N25: =(1-PERCENTRANK(J$3:J$202,J25))*'Input Resturant Brands Scoring '!$B$5 -> 10.044 | O25: =(1-PERCENTRANK(I$3:I$202,I25))*'Input Resturant Brands Scoring '!$B$6 -> 3.804 | P25: =sum(N25:O25) -> 13.848 | Q25: =PERCENTRANK(L$3:L$202,L25)*'Input Resturant Brands Scoring '!$B$7 -> 28.315 | R25: =M25+N25+O25+Q25 -> 73.278 | S25: =RANK(R25,R$3:R$202,0) -> 10 | T25: =IF(S25<=10,"S",IF(S25<=50,"A",IF(S25<=150,"B","C"))) -> S | U25: =G25*F25*B25 -> 997970.69 | V25: =MIN(0.3, MAX(0.1, IF(T25="S", G25-0.02, IF(T25="A", G25-0.005, IF(T25="B", G25+0.02, G25+0.03))))) -> 0.24 | W25: =V25-G25 -> -0.02 | X25: =IF(T25="S", B25*(1+'Input Fee and Elasticity Inputs'!$B$9), IF(T25="A", B25*(1+'Input Fee and Elasticity Inputs'!$B$10), IF(T25="B", B25*(1+'Input Fee and Elasticity Inputs'!$B$11), B25*(1+'Input Fee and Elasticity Inputs'!$B$12)))) -> 174470.4 | Y25: =F25*V25 -> 6.336 | Z25: =Y25*X25 -> 1105444.5 | AA25: =Z25-U25 -> 107473.77
A26: Chipotle | B26: 138528 | C26: 27 | D26: 38 | E26: 0.47 | F26: 16.2 | G26: 0.22 | H26: 0.0832 | I26: 0.022515171 | J26: 5 | K26: =if(C26>20,"Enterprise","SMB") -> Enterprise | L26: =F26*G26 -> 3.564 | M26: =PERCENTRANK(B$3:B$202,B26)*'Input Resturant Brands Scoring '!$B$3 -> 30.94 | N26: =(1-PERCENTRANK(J$3:J$202,J26))*'Input Resturant Brands Scoring '!$B$5 -> 15.462 | O26: =(1-PERCENTRANK(I$3:I$202,I26))*'Input Resturant Brands Scoring '!$B$6 -> 4.104 | P26: =sum(N26:O26) -> 19.566 | Q26: =PERCENTRANK(L$3:L$202,L26)*'Input Resturant Brands Scoring '!$B$7 -> 1.575 | R26: =M26+N26+O26+Q26 -> 52.081 | S26: =RANK(R26,R$3:R$202,0) -> 95 | T26: =IF(S26<=10,"S",IF(S26<=50,"A",IF(S26<=150,"B","C"))) -> B | U26: =G26*F26*B26 -> 493713.79 | V26: =MIN(0.3, MAX(0.1, IF(T26="S", G26-0.02, IF(T26="A", G26-0.005, IF(T26="B", G26+0.02, G26+0.03))))) -> 0.24 | W26: =V26-G26 -> 0.02 | X26: =IF(T26="S", B26*(1+'Input Fee and Elasticity Inputs'!$B$9), IF(T26="A", B26*(1+'Input Fee and Elasticity Inputs'!$B$10), IF(T26="B", B26*(1+'Input Fee and Elasticity Inputs'!$B$11), B26*(1+'Input Fee and Elasticity Inputs'!$B$12)))) -> 131601.6 | Y26: =F26*V26 -> 3.888 | Z26: =Y26*X26 -> 511667.02 | AA26: =Z26-U26 -> 17953.229
A27: Five Guys Enterprises, LLC | B27: 134400 | C27: 19 | D27: 51 | E27: 0.59 | F27: 18 | G27: 0.3 | H27: 0.086 | I27: 0.032553006 | J27: 55 | K27: =if(C27>20,"Enterprise","SMB") -> SMB | L27: =F27*G27 -> 5.4 | M27: =PERCENTRANK(B$3:B$202,B27)*'Input Resturant Brands Scoring '!$B$3 -> 30.765 | N27: =(1-PERCENTRANK(J$3:J$202,J27))*'Input Resturant Brands Scoring '!$B$5 -> 0.09 | O27: =(1-PERCENTRANK(I$3:I$202,I27))*'Input Resturant Brands Scoring '!$B$6 -> 0.3 | P27: =sum(N27:O27) -> 0.39 | Q27: =PERCENTRANK(L$3:L$202,L27)*'Input Resturant Brands Scoring '!$B$7 -> 17.045 | R27: =M27+N27+O27+Q27 -> 48.2 | S27: =RANK(R27,R$3:R$202,0) -> 114 | T27: =IF(S27<=10,"S",IF(S27<=50,"A",IF(S27<=150,"B","C"))) -> B | U27: =G27*F27*B27 -> 725760 | V27: =MIN(0.3, MAX(0.1, IF(T27="S", G27-0.02, IF(T27="A", G27-0.005, IF(T27="B", G27+0.02, G27+0.03))))) -> 0.3 | W27: =V27-G27 -> 0 | X27: =IF(T27="S", B27*(1+'Input Fee and Elasticity Inputs'!$B$9), IF(T27="A", B27*(1+'Input Fee and Elasticity Inputs'!$B$10), IF(T27="B", B27*(1+'Input Fee and Elasticity Inputs'!$B$11), B27*(1+'Input Fee and Elasticity Inputs'!$B$12)))) -> 127680 | Y27: =F27*V27 -> 5.4 | Z27: =Y27*X27 -> 689472 | AA27: =Z27-U27 -> -36288
... A202: Chickie's & Pete's | B202: 2592 | C202: 6 | D202: 38 | E202: 0.39 | F202: 28.3 | G202: 0.26 | H202: 0.092 | I202: 0.013036725 | J202: 6 | K202: =if(C202>20,"Enterprise","SMB") -> SMB | L202: =F202*G202 -> 7.358 | M202: =PERCENTRANK(B$3:B$202,B202)*'Input Resturant Brands Scoring '!$B$3 -> 0 | N202: =(1-PERCENTRANK(J$3:J$202,J202))*'Input Resturant Brands Scoring '!$B$5 -> 14.022 | O202: =(1-PERCENTRANK(I$3:I$202,I202))*'Input Resturant Brands Scoring '!$B$6 -> 10.86 | P202: =sum(N202:O202) -> 24.882 | Q202: =PERCENTRANK(L$3:L$202,L202)*'Input Resturant Brands Scoring '!$B$7 -> 30.415 | R202: =M202+N202+O202+Q202 -> 55.297 | S202: =RANK(R202,R$3:R$202,0) -> 74 | T202: =IF(S202<=10,"S",IF(S202<=50,"A",IF(S202<=150,"B","C"))) -> B | U202: =G202*F202*B202 -> 19071.936 | V202: =MIN(0.3, MAX(0.1, IF(T202="S", G202-0.02, IF(T202="A", G202-0.005, IF(T202="B", G202+0.02, G202+0.03))))) -> 0.28 | W202: =V202-G202 -> 0.02 | X202: =IF(T202="S", B202*(1+'Input Fee and Elasticity Inputs'!$B$9), IF(T202="A", B202*(1+'Input Fee and Elasticity Inputs'!$B$10), IF(T202="B", B202*(1+'Input Fee and Elasticity Inputs'!$B$11), B202*(1+'Input Fee and Elasticity Inputs'!$B$12)))) -> 2462.4 | Y202: =F202*V202 -> 7.924 | Z202: =Y202*X202 -> 19512.058 | AA202: =Z202-U202 -> 440.1216

Sheet Sheet5
A1: {='RAW Restaurant Brands Dataset'!A:J} -> Brand Name | B1: Annualized Trips | C1: Active Locations | D1: Total Locations | E1: % Franchised | F1: Avg. Basket Size | G1: Marketplace Fee | H1: %Orders from First Time Eaters | I1: Order Defect Rate | J1: Avg. Courier Wait Time (min) | K1: Type | L1: Rev / Order (Helper) | M1: Volume Score | N1: Wait Time Score | O1: Defect Score | P1: Quality Score Total | Q1: Econ Score | R1: Total Score | S1: Rank | T1: Tier | U1: Current Rev | V1: Target Fee | W1: Fee Change | X1: New Trips | Y1: New Rev / Order | Z1: New Revenue | AA1: Revenue Delta
A2: Original Tommy's Hamburgers | B2: 1068012 | C2: 482 | D2: 753 | E2: 0.69 | F2: 16.8 | G2: 0.25 | H2: 0.0468 | I2: 0.028940039 | J2: 7 | K2: =if(C2>20,"Enterprise","SMB") -> Enterprise | L2: =F2*G2 -> 4.2 | M2: =PERCENTRANK(B$2:B$201,B2)*'Input Resturant Brands Scoring '!$B$3 -> 35 | N2: =(1-PERCENTRANK(J$2:J$201,J2))*'Input Resturant Brands Scoring '!$B$5 -> 12.204 | O2: =(1-PERCENTRANK(I$2:I$201,I2))*'Input Resturant Brands Scoring '!$B$6 -> 1.212 | P2: =sum(N2:O2) -> 13.416 | Q2: =PERCENTRANK(L$2:L$201,L2)*'Input Resturant Brands Scoring '!$B$7 -> 5.285 | R2: =M2+N2+O2+Q2 -> 53.701 | S2: =RANK(R2,R$2:R$201,0) -> 87 | T2: =IF(S2<=10,"S",IF(S2<=50,"A",IF(S2<=150,"B","C"))) -> B | U2: =G2*F2*B2 -> 4485650.4 | V2: =MIN(0.3, MAX(0.1, IF(T2="S", G2-0.02, IF(T2="A", G2-0.005, IF(T2="B", G2+0.02, G2+0.03))))) -> 0.27 | W2: =V2-G2 -> 0.02 | X2: =IF(T2="S", B2*(1+'Input Fee and Elasticity Inputs'!$B$9), IF(T2="A", B2*(1+'Input Fee and Elasticity Inputs'!$B$10), IF(T2="B", B2*(1+'Input Fee and Elasticity Inputs'!$B$11), B2*(1+'Input Fee and Elasticity Inputs'!$B$12)))) -> 1014611.4 | Y2: =F2*V2 -> 4.536 | Z2: =Y2*X2 -> 4602277.3 | AA2: =Z2-U2 -> 116626.91
A3: Baja Fresh Mexican Grill | B3: 1018080 | C3: 556 | D3: 783 | E3: 0.96 | F3: 18.5 | G3: 0.17 | H3: 0.0652 | I3: 0.027053132 | J3: 4 | K3: =if(C3>20,"Enterprise","SMB") -> Enterprise | L3: =F3*G3 -> 3.145 | M3: =PERCENTRANK(B$2:B$201,B3)*'Input Resturant Brands Scoring '!$B$3 -> 34.825 | N3: =(1-PERCENTRANK(J$2:J$201,J3))*'Input Resturant Brands Scoring '!$B$5 -> 17.1 | O3: =(1-PERCENTRANK(I$2:I$201,I3))*'Input Resturant Brands Scoring '!$B$6 -> 1.872 | P3: =sum(N3:O3) -> 18.972 | Q3: =PERCENTRANK(L$2:L$201,L3)*'Input Resturant Brands Scoring '!$B$7 -> 0.7 | R3: =M3+N3+O3+Q3 -> 54.497 | S3: =RANK(R3,R$2:R$201,0) -> 82 | T3: =IF(S3<=10,"S",IF(S3<=50,"A",IF(S3<=150,"B","C"))) -> B | U3: =G3*F3*B3 -> 3201861.6 | V3: =MIN(0.3, MAX(0.1, IF(T3="S", G3-0.02, IF(T3="A", G3-0.005, IF(T3="B", G3+0.02, G3+0.03))))) -> 0.19 | W3: =V3-G3 -> 0.02 | X3: =IF(T3="S", B3*(1+'Input Fee and Elasticity Inputs'!$B$9), IF(T3="A", B3*(1+'Input Fee and Elasticity Inputs'!$B$10), IF(T3="B", B3*(1+'Input Fee and Elasticity Inputs'!$B$11), B3*(1+'Input Fee and Elasticity Inputs'!$B$12)))) -> 967176 | Y3: =F3*V3 -> 3.515 | Z3: =Y3*X3 -> 3399623.6 | AA3: =Z3-U3 -> 197762.04
A4: Little Greek | B4: 775008 | C4: 388 | D4: 668 | E4: 0.23 | F4: 22.4 | G4: 0.3 | H4: 0.0736 | I4: 0.029747822 | J4: 45 | K4: =if(C4>20,"Enterprise","SMB") -> Enterprise | L4: =F4*G4 -> 6.72 | M4: =PERCENTRANK(B$2:B$201,B4)*'Input Resturant Brands Scoring '!$B$3 -> 34.65 | N4: =(1-PERCENTRANK(J$2:J$201,J4))*'Input Resturant Brands Scoring '!$B$5 -> 0.27 | O4: =(1-PERCENTRANK(I$2:I$201,I4))*'Input Resturant Brands Scoring '!$B$6 -> 0.9 | P4: =sum(N4:O4) -> 1.17 | Q4: =PERCENTRANK(L$2:L$201,L4)*'Input Resturant Brands Scoring '!$B$7 -> 27.615 | R4: =M4+N4+O4+Q4 -> 63.435 | S4: =RANK(R4,R$2:R$201,0) -> 42 | T4: =IF(S4<=10,"S",IF(S4<=50,"A",IF(S4<=150,"B","C"))) -> A | U4: =G4*F4*B4 -> 5208053.8 | V4: =MIN(0.3, MAX(0.1, IF(T4="S", G4-0.02, IF(T4="A", G4-0.005, IF(T4="B", G4+0.02, G4+0.03))))) -> 0.295 | W4: =V4-G4 -> -0.005 | X4: =IF(T4="S", B4*(1+'Input Fee and Elasticity Inputs'!$B$9), IF(T4="A", B4*(1+'Input Fee and Elasticity Inputs'!$B$10), IF(T4="B", B4*(1+'Input Fee and Elasticity Inputs'!$B$11), B4*(1+'Input Fee and Elasticity Inputs'!$B$12)))) -> 852508.8 | Y4: =F4*V4 -> 6.608 | Z4: =Y4*X4 -> 5633378.2 | AA4: =Z4-U4 -> 425324.39
A5: Tocaya Organica | B5: 264384 | C5: 299 | D5: 320 | E5: 0.56 | F5: 26 | G5: 0.28 | H5: 0.048 | I5: 0.029179748 | J5: 21 | K5: =if(C5>20,"Enterprise","SMB") -> Enterprise | L5: =F5*G5 -> 7.28 | M5: =PERCENTRANK(B$2:B$201,B5)*'Input Resturant Brands Scoring '!$B$3 -> 34.475 | N5: =(1-PERCENTRANK(J$2:J$201,J5))*'Input Resturant Brands Scoring '!$B$5 -> 3.348 | O5: =(1-PERCENTRANK(I$2:I$201,I5))*'Input Resturant Brands Scoring '!$B$6 -> 1.02 | P5: =sum(N5:O5) -> 4.368 | Q5: =PERCENTRANK(L$2:L$201,L5)*'Input Resturant Brands Scoring '!$B$7 -> 30.065 | R5: =M5+N5+O5+Q5 -> 68.908 | S5: =RANK(R5,R$2:R$201,0) -> 23 | T5: =IF(S5<=10,"S",IF(S5<=50,"A",IF(S5<=150,"B","C"))) -> A | U5: =G5*F5*B5 -> 1924715.5 | V5: =MIN(0.3, MAX(0.1, IF(T5="S", G5-0.02, IF(T5="A", G5-0.005, IF(T5="B", G5+0.02, G5+0.03))))) -> 0.275 | W5: =V5-G5 -> -0.005 | X5: =IF(T5="S", B5*(1+'Input Fee and Elasticity Inputs'!$B$9), IF(T5="A", B5*(1+'Input Fee and Elasticity Inputs'!$B$10), IF(T5="B", B5*(1+'Input Fee and Elasticity Inputs'!$B$11), B5*(1+'Input Fee and Elasticity Inputs'!$B$12)))) -> 290822.4 | Y5: =F5*V5 -> 7.15 | Z5: =Y5*X5 -> 2079380.2 | AA5: =Z5-U5 -> 154664.64
A6: Freshii | B6: 238560 | C6: 82 | D6: 191 | E6: 0.22 | F6: 21.7 | G6: 0.25 | H6: 0.0452 | I6: 0.017983438 | J6: 5 | K6: =if(C6>20,"Enterprise","SMB") -> Enterprise | L6: =F6*G6 -> 5.425 | M6: =PERCENTRANK(B$2:B$201,B6)*'Input Resturant Brands Scoring '!$B$3 -> 34.3 | N6: =(1-PERCENTRANK(J$2:J$201,J6))*'Input Resturant Brands Scoring '!$B$5 -> 15.462 | O6: =(1-PERCENTRANK(I$2:I$201,I6))*'Input Resturant Brands Scoring '!$B$6 -> 6.216 | P6: =sum(N6:O6) -> 21.678 | Q6: =PERCENTRANK(L$2:L$201,L6)*'Input Resturant Brands Scoring '!$B$7 -> 17.78 | R6: =M6+N6+O6+Q6 -> 73.758 | S6: =RANK(R6,R$2:R$201,0) -> 9 | T6: =IF(S6<=10,"S",IF(S6<=50,"A",IF(S6<=150,"B","C"))) -> S | U6: =G6*F6*B6 -> 1294188 | V6: =MIN(0.3, MAX(0.1, IF(T6="S", G6-0.02, IF(T6="A", G6-0.005, IF(T6="B", G6+0.02, G6+0.03))))) -> 0.23 | W6: =V6-G6 -> -0.02 | X6: =IF(T6="S", B6*(1+'Input Fee and Elasticity Inputs'!$B$9), IF(T6="A", B6*(1+'Input Fee and Elasticity Inputs'!$B$10), IF(T6="B", B6*(1+'Input Fee and Elasticity Inputs'!$B$11), B6*(1+'Input Fee and Elasticity Inputs'!$B$12)))) -> 286272 | Y6: =F6*V6 -> 4.991 | Z6: =Y6*X6 -> 1428783.6 | AA6: =Z6-U6 -> 134595.55
A7: Carl's Jr. Restaurants | B7: 226872 | C7: 53 | D7: 58 | E7: 0.76 | F7: 16.6 | G7: 0.26 | H7: 0.0412 | I7: 0.016135534 | J7: 5 | K7: =if(C7>20,"Enterprise","SMB") -> Enterprise | L7: =F7*G7 -> 4.316 | M7: =PERCENTRANK(B$2:B$201,B7)*'Input Resturant Brands Scoring '!$B$3 -> 34.125 | N7: =(1-PERCENTRANK(J$2:J$201,J7))*'Input Resturant Brands Scoring '!$B$5 -> 15.462 | O7: =(1-PERCENTRANK(I$2:I$201,I7))*'Input Resturant Brands Scoring '!$B$6 -> 7.896 | P7: =sum(N7:O7) -> 23.358 | Q7: =PERCENTRANK(L$2:L$201,L7)*'Input Resturant Brands Scoring '!$B$7 -> 5.81 | R7: =M7+N7+O7+Q7 -> 63.293 | S7: =RANK(R7,R$2:R$201,0) -> 44 | T7: =IF(S7<=10,"S",IF(S7<=50,"A",IF(S7<=150,"B","C"))) -> A | U7: =G7*F7*B7 -> 979179.55 | V7: =MIN(0.3, MAX(0.1, IF(T7="S", G7-0.02, IF(T7="A", G7-0.005, IF(T7="B", G7+0.02, G7+0.03))))) -> 0.255 | W7: =V7-G7 -> -0.005 | X7: =IF(T7="S", B7*(1+'Input Fee and Elasticity Inputs'!$B$9), IF(T7="A", B7*(1+'Input Fee and Elasticity Inputs'!$B$10), IF(T7="B", B7*(1+'Input Fee and Elasticity Inputs'!$B$11), B7*(1+'Input Fee and Elasticity Inputs'!$B$12)))) -> 249559.2 | Y7: =F7*V7 -> 4.233 | Z7: =Y7*X7 -> 1056384.1 | AA7: =Z7-U7 -> 77204.542
A8: Pita Pit | B8: 224136 | C8: 42 | D8: 86 | E8: 0.27 | F8: 16 | G8: 0.3 | H8: 0.07 | I8: 0.016712727 | J8: 14 | K8: =if(C8>20,"Enterprise","SMB") -> Enterprise | L8: =F8*G8 -> 4.8 | M8: =PERCENTRANK(B$2:B$201,B8)*'Input Resturant Brands Scoring '!$B$3 -> 33.95 | N8: =(1-PERCENTRANK(J$2:J$201,J8))*'Input Resturant Brands Scoring '!$B$5 -> 6.426 | O8: =(1-PERCENTRANK(I$2:I$201,I8))*'Input Resturant Brands Scoring '!$B$6 -> 7.236 | P8: =sum(N8:O8) -> 13.662 | Q8: =PERCENTRANK(L$2:L$201,L8)*'Input Resturant Brands Scoring '!$B$7 -> 10.745 | R8: =M8+N8+O8+Q8 -> 58.357 | S8: =RANK(R8,R$2:R$201,0) -> 60 | T8: =IF(S8<=10,"S",IF(S8<=50,"A",IF(S8<=150,"B","C"))) -> B | U8: =G8*F8*B8 -> 1075852.8 | V8: =MIN(0.3, MAX(0.1, IF(T8="S", G8-0.02, IF(T8="A", G8-0.005, IF(T8="B", G8+0.02, G8+0.03))))) -> 0.3 | W8: =V8-G8 -> 0 | X8: =IF(T8="S", B8*(1+'Input Fee and Elasticity Inputs'!$B$9), IF(T8="A", B8*(1+'Input Fee and Elasticity Inputs'!$B$10), IF(T8="B", B8*(1+'Input Fee and Elasticity Inputs'!$B$11), B8*(1+'Input Fee and Elasticity Inputs'!$B$12)))) -> 212929.2 | Y8: =F8*V8 -> 4.8 | Z8: =Y8*X8 -> 1022060.2 | AA8: =Z8-U8 -> -53792.64
A9: Cici's Enterprises | B9: 221760 | C9: 72 | D9: 300 | E9: 0.37 | F9: 15.1 | G9: 0.24 | H9: 0.0604 | I9: 0.014803598 | J9: 28 | K9: =if(C9>20,"Enterprise","SMB") -> Enterprise | L9: =F9*G9 -> 3.624 | M9: =PERCENTRANK(B$2:B$201,B9)*'Input Resturant Brands Scoring '!$B$3 -> 33.775 | N9: =(1-PERCENTRANK(J$2:J$201,J9))*'Input Resturant Brands Scoring '!$B$5 -> 1.62 | O9: =(1-PERCENTRANK(I$2:I$201,I9))*'Input Resturant Brands Scoring '!$B$6 -> 8.808 | P9: =sum(N9:O9) -> 10.428 | Q9: =PERCENTRANK(L$2:L$201,L9)*'Input Resturant Brands Scoring '!$B$7 -> 1.75 | R9: =M9+N9+O9+Q9 -> 45.953 | S9: =RANK(R9,R$2:R$201,0) -> 130 | T9: =IF(S9<=10,"S",IF(S9<=50,"A",IF(S9<=150,"B","C"))) -> B | U9: =G9*F9*B9 -> 803658.24 | V9: =MIN(0.3, MAX(0.1, IF(T9="S", G9-0.02, IF(T9="A", G9-0.005, IF(T9="B", G9+0.02, G9+0.03))))) -> 0.26 | W9: =V9-G9 -> 0.02 | X9: =IF(T9="S", B9*(1+'Input Fee and Elasticity Inputs'!$B$9), IF(T9="A", B9*(1+'Input Fee and Elasticity Inputs'!$B$10), IF(T9="B", B9*(1+'Input Fee and Elasticity Inputs'!$B$11), B9*(1+'Input Fee and Elasticity Inputs'!$B$12)))) -> 210672 | Y9: =F9*V9 -> 3.926 | Z9: =Y9*X9 -> 827098.27 | AA9: =Z9-U9 -> 23440.032
A10: Gus's World Famous Fried Chicken | B10: 216372 | C10: 93 | D10: 930 | E10: 0.55 | F10: 19.8 | G10: 0.26 | H10: 0.0892 | I10: 0.014041635 | J10: 13 | K10: =if(C10>20,"Enterprise","SMB") -> Enterprise | L10: =F10*G10 -> 5.148 | M10: =PERCENTRANK(B$2:B$201,B10)*'Input Resturant Brands Scoring '!$B$3 -> 33.6 | N10: =(1-PERCENTRANK(J$2:J$201,J10))*'Input Resturant Brands Scoring '!$B$5 -> 7.056 | O10: =(1-PERCENTRANK(I$2:I$201,I10))*'Input Resturant Brands Scoring '!$B$6 -> 9.948 | P10: =sum(N10:O10) -> 17.004 | Q10: =PERCENTRANK(L$2:L$201,L10)*'Input Resturant Brands Scoring '!$B$7 -> 14.595 | R10: =M10+N10+O10+Q10 -> 65.199 | S10: =RANK(R10,R$2:R$201,0) -> 35 | T10: =IF(S10<=10,"S",IF(S10<=50,"A",IF(S10<=150,"B","C"))) -> A | U10: =G10*F10*B10 -> 1113883.1 | V10: =MIN(0.3, MAX(0.1, IF(T10="S", G10-0.02, IF(T10="A", G10-0.005, IF(T10="B", G10+0.02, G10+0.03))))) -> 0.255 | W10: =V10-G10 -> -0.005 | X10: =IF(T10="S", B10*(1+'Input Fee and Elasticity Inputs'!$B$9), IF(T10="A", B10*(1+'Input Fee and Elasticity Inputs'!$B$10), IF(T10="B", B10*(1+'Input Fee and Elasticity Inputs'!$B$11), B10*(1+'Input Fee and Elasticity Inputs'!$B$12)))) -> 238009.2 | Y10: =F10*V10 -> 5.049 | Z10: =Y10*X10 -> 1201708.5 | AA10: =Z10-U10 -> 87825.395
A11: The Buffalo Spot | B11: 215280 | C11: 41 | D11: 216 | E11: 0.93 | F11: 17.4 | G11: 0.25 | H11: 0.0756 | I11: 0.014341467 | J11: 37 | K11: =if(C11>20,"Enterprise","SMB") -> Enterprise | L11: =F11*G11 -> 4.35 | M11: =PERCENTRANK(B$2:B$201,B11)*'Input Resturant Brands Scoring '!$B$3 -> 33.425 | N11: =(1-PERCENTRANK(J$2:J$201,J11))*'Input Resturant Brands Scoring '!$B$5 -> 0.81 | O11: =(1-PERCENTRANK(I$2:I$201,I11))*'Input Resturant Brands Scoring '!$B$6 -> 9.288 | P11: =sum(N11:O11) -> 10.098 | Q11: =PERCENTRANK(L$2:L$201,L11)*'Input Resturant Brands Scoring '!$B$7 -> 6.51 | R11: =M11+N11+O11+Q11 -> 50.033 | S11: =RANK(R11,R$2:R$201,0) -> 107 | T11: =IF(S11<=10,"S",IF(S11<=50,"A",IF(S11<=150,"B","C"))) -> B | U11: =G11*F11*B11 -> 936468 | V11: =MIN(0.3, MAX(0.1, IF(T11="S", G11-0.02, IF(T11="A", G11-0.005, IF(T11="B", G11+0.02, G11+0.03))))) -> 0.27 | W11: =V11-G11 -> 0.02 | X11: =IF(T11="S", B11*(1+'Input Fee and Elasticity Inputs'!$B$9), IF(T11="A", B11*(1+'Input Fee and Elasticity Inputs'!$B$10), IF(T11="B", B11*(1+'Input Fee and Elasticity Inputs'!$B$11), B11*(1+'Input Fee and Elasticity Inputs'!$B$12)))) -> 204516 | Y11: =F11*V11 -> 4.698 | Z11: =Y11*X11 -> 960816.17 | AA11: =Z11-U11 -> 24348.168
A12: Wings Over | B12: 211200 | C12: 38 | D12: 46 | E12: 0.68 | F12: 21.4 | G12: 0.24 | H12: 0.0336 | I12: 0.013798989 | J12: 3 | K12: =if(C12>20,"Enterprise","SMB") -> Enterprise | L12: =F12*G12 -> 5.136 | M12: =PERCENTRANK(B$2:B$201,B12)*'Input Resturant Brands Scoring '!$B$3 -> 33.25 | N12: =(1-PERCENTRANK(J$2:J$201,J12))*'Input Resturant Brands Scoring '!$B$5 -> 18 | O12: =(1-PERCENTRANK(I$2:I$201,I12))*'Input Resturant Brands Scoring '!$B$6 -> 10.188 | P12: =sum(N12:O12) -> 28.188 | Q12: =PERCENTRANK(L$2:L$201,L12)*'Input Resturant Brands Scoring '!$B$7 -> 14.42 | R12: =M12+N12+O12+Q12 -> 75.858 | S12: =RANK(R12,R$2:R$201,0) -> 7 | T12: =IF(S12<=10,"S",IF(S12<=50,"A",IF(S12<=150,"B","C"))) -> S | U12: =G12*F12*B12 -> 1084723.2 | V12: =MIN(0.3, MAX(0.1, IF(T12="S", G12-0.02, IF(T12="A", G12-0.005, IF(T12="B", G12+0.02, G12+0.03))))) -> 0.22 | W12: =V12-G12 -> -0.02 | X12: =IF(T12="S", B12*(1+'Input Fee and Elasticity Inputs'!$B$9), IF(T12="A", B12*(1+'Input Fee and Elasticity Inputs'!$B$10), IF(T12="B", B12*(1+'Input Fee and Elasticity Inputs'!$B$11), B12*(1+'Input Fee and Elasticity Inputs'!$B$12)))) -> 253440 | Y12: =F12*V12 -> 4.708 | Z12: =Y12*X12 -> 1193195.5 | AA12: =Z12-U12 -> 108472.32
A13: Bed-Stuy Fish Fry | B13: 209760 | C13: 98 | D13: 184 | E13: 0.59 | F13: 25.4 | G13: 0.3 | H13: 0.0868 | I13: 0.031642305 | J13: 34 | K13: =if(C13>20,"Enterprise","SMB") -> Enterprise | L13: =F13*G13 -> 7.62 | M13: =PERCENTRANK(B$2:B$201,B13)*'Input Resturant Brands Scoring '!$B$3 -> 33.075 | N13: =(1-PERCENTRANK(J$2:J$201,J13))*'Input Resturant Brands Scoring '!$B$5 -> 1.08 | O13: =(1-PERCENTRANK(I$2:I$201,I13))*'Input Resturant Brands Scoring '!$B$6 -> 0.48 | P13: =sum(N13:O13) -> 1.56 | Q13: =PERCENTRANK(L$2:L$201,L13)*'Input Resturant Brands Scoring '!$B$7 -> 31.85 | R13: =M13+N13+O13+Q13 -> 66.485 | S13: =RANK(R13,R$2:R$201,0) -> 31 | T13: =IF(S13<=10,"S",IF(S13<=50,"A",IF(S13<=150,"B","C"))) -> A | U13: =G13*F13*B13 -> 1598371.2 | V13: =MIN(0.3, MAX(0.1, IF(T13="S", G13-0.02, IF(T13="A", G13-0.005, IF(T13="B", G13+0.02, G13+0.03))))) -> 0.295 | W13: =V13-G13 -> -0.005 | X13: =IF(T13="S", B13*(1+'Input Fee and Elasticity Inputs'!$B$9), IF(T13="A", B13*(1+'Input Fee and Elasticity Inputs'!$B$10), IF(T13="B", B13*(1+'Input Fee and Elasticity Inputs'!$B$11), B13*(1+'Input Fee and Elasticity Inputs'!$B$12)))) -> 230736 | Y13: =F13*V13 -> 7.493 | Z13: =Y13*X13 -> 1728904.8 | AA13: =Z13-U13 -> 130533.65
A14: Shari's Cafe & Pies | B14: 209088 | C14: 42 | D14: 86 | E14: 0.99 | F14: 20.6 | G14: 0.29 | H14: 0.0368 | I14: 0.034377076 | J14: 10 | K14: =if(C14>20,"Enterprise","SMB") -> Enterprise | L14: =F14*G14 -> 5.974 | M14: =PERCENTRANK(B$2:B$201,B14)*'Input Resturant Brands Scoring '!$B$3 -> 32.9 | N14: =(1-PERCENTRANK(J$2:J$201,J14))*'Input Resturant Brands Scoring '!$B$5 -> 9.054 | O14: =(1-PERCENTRANK(I$2:I$201,I14))*'Input Resturant Brands Scoring '!$B$6 -> 0.12 | P14: =sum(N14:O14) -> 9.174 | Q14: =PERCENTRANK(L$2:L$201,L14)*'Input Resturant Brands Scoring '!$B$7 -> 22.855 | R14: =M14+N14+O14+Q14 -> 64.929 | S14: =RANK(R14,R$2:R$201,0) -> 36 | T14: =IF(S14<=25,"S",IF(S14<=50,"A",IF(S14<=150,"B","C"))) -> A | U14: =G14*F14*B14 -> 1249091.7 | V14: =MIN(0.3, MAX(0.1, IF(T14="S", G14-0.02, IF(T14="A", G14-0.005, IF(T14="B", G14+0.02, G14+0.03))))) -> 0.285 | W14: =V14-G14 -> -0.005 | X14: =IF(T14="S", B14*(1+'Input Fee and Elasticity Inputs'!$B$9), IF(T14="A", B14*(1+'Input Fee and Elasticity Inputs'!$B$10), IF(T14="B", B14*(1+'Input Fee and Elasticity Inputs'!$B$11), B14*(1+'Input Fee and Elasticity Inputs'!$B$12)))) -> 229996.8 | Y14: =F14*V14 -> 5.871 | Z14: =Y14*X14 -> 1350311.2 | AA14: =Z14-U14 -> 101219.5
A15: Romano's Macaroni Grill | B15: 209040 | C15: 41 | D15: 103 | E15: 0.28 | F15: 34.4 | G15: 0.25 | H15: 0.1328 | I15: 0.031960196 | J15: 24 | K15: =if(C15>20,"Enterprise","SMB") -> Enterprise | L15: =F15*G15 -> 8.6 | M15: =PERCENTRANK(B$2:B$201,B15)*'Input Resturant Brands Scoring '!$B$3 -> 32.725 | N15: =(1-PERCENTRANK(J$2:J$201,J15))*'Input Resturant Brands Scoring '!$B$5 -> 2.448 | O15: =(1-PERCENTRANK(I$2:I$201,I15))*'Input Resturant Brands Scoring '!$B$6 -> 0.42 | P15: =sum(N15:O15) -> 2.868 | Q15: =PERCENTRANK(L$2:L$201,L15)*'Input Resturant Brands Scoring '!$B$7 -> 33.775 | R15: =M15+N15+O15+Q15 -> 69.368 | S15: =RANK(R15,R$2:R$201,0) -> 21 | T15: =IF(S15<=10,"S",IF(S15<=50,"A",IF(S15<=150,"B","C"))) -> A | U15: =G15*F15*B15 -> 1797744 | V15: =MIN(0.3, MAX(0.1, IF(T15="S", G15-0.02, IF(T15="A", G15-0.005, IF(T15="B", G15+0.02, G15+0.03))))) -> 0.245 | W15: =V15-G15 -> -0.005 | X15: =IF(T15="S", B15*(1+'Input Fee and Elasticity Inputs'!$B$9), IF(T15="A", B15*(1+'Input Fee and Elasticity Inputs'!$B$10), IF(T15="B", B15*(1+'Input Fee and Elasticity Inputs'!$B$11), B15*(1+'Input Fee and Elasticity Inputs'!$B$12)))) -> 229944 | Y15: =F15*V15 -> 8.428 | Z15: =Y15*X15 -> 1937968 | AA15: =Z15-U15 -> 140224.03
A16: Village Inn | B16: 183120 | C16: 65 | D16: 73 | E16: 0.46 | F16: 20.2 | G16: 0.27 | H16: 0.0912 | I16: 0.032994188 | J16: 20 | K16: =if(C16>20,"Enterprise","SMB") -> Enterprise | L16: =F16*G16 -> 5.454 | M16: =PERCENTRANK(B$2:B$201,B16)*'Input Resturant Brands Scoring '!$B$3 -> 32.55 | N16: =(1-PERCENTRANK(J$2:J$201,J16))*'Input Resturant Brands Scoring '!$B$5 -> 3.528 | O16: =(1-PERCENTRANK(I$2:I$201,I16))*'Input Resturant Brands Scoring '!$B$6 -> 0.24 | P16: =sum(N16:O16) -> 3.768 | Q16: =PERCENTRANK(L$2:L$201,L16)*'Input Resturant Brands Scoring '!$B$7 -> 18.305 | R16: =M16+N16+O16+Q16 -> 54.623 | S16: =RANK(R16,R$2:R$201,0) -> 78 | T16: =IF(S16<=10,"S",IF(S16<=50,"A",IF(S16<=150,"B","C"))) -> B | U16: =G16*F16*B16 -> 998736.48 | V16: =MIN(0.3, MAX(0.1, IF(T16="S", G16-0.02, IF(T16="A", G16-0.005, IF(T16="B", G16+0.02, G16+0.03))))) -> 0.29 | W16: =V16-G16 -> 0.02 | X16: =IF(T16="S", B16*(1+'Input Fee and Elasticity Inputs'!$B$9), IF(T16="A", B16*(1+'Input Fee and Elasticity Inputs'!$B$10), IF(T16="B", B16*(1+'Input Fee and Elasticity Inputs'!$B$11), B16*(1+'Input Fee and Elasticity Inputs'!$B$12)))) -> 173964 | Y16: =F16*V16 -> 5.858 | Z16: =Y16*X16 -> 1019081.1 | AA16: =Z16-U16 -> 20344.632
A17: Gong Cha | B17: 173052 | C17: 51 | D17: 204 | E17: 0.84 | F17: 13.7 | G17: 0.3 | H17: 0.0692 | I17: 0.01429629 | J17: 18 | K17: =if(C17>20,"Enterprise","SMB") -> Enterprise | L17: =F17*G17 -> 4.11 | M17: =PERCENTRANK(B$2:B$201,B17)*'Input Resturant Brands Scoring '!$B$3 -> 32.375 | N17: =(1-PERCENTRANK(J$2:J$201,J17))*'Input Resturant Brands Scoring '!$B$5 -> 3.978 | O17: =(1-PERCENTRANK(I$2:I$201,I17))*'Input Resturant Brands Scoring '!$B$6 -> 9.468 | P17: =sum(N17:O17) -> 13.446 | Q17: =PERCENTRANK(L$2:L$201,L17)*'Input Resturant Brands Scoring '!$B$7 -> 4.585 | R17: =M17+N17+O17+Q17 -> 50.406 | S17: =RANK(R17,R$2:R$201,0) -> 102 | T17: =IF(S17<=10,"S",IF(S17<=50,"A",IF(S17<=150,"B","C"))) -> B | U17: =G17*F17*B17 -> 711243.72 | V17: =MIN(0.3, MAX(0.1, IF(T17="S", G17-0.02, IF(T17="A", G17-0.005, IF(T17="B", G17+0.02, G17+0.03))))) -> 0.3 | W17: =V17-G17 -> 0 | X17: =IF(T17="S", B17*(1+'Input Fee and Elasticity Inputs'!$B$9), IF(T17="A", B17*(1+'Input Fee and Elasticity Inputs'!$B$10), IF(T17="B", B17*(1+'Input Fee and Elasticity Inputs'!$B$11), B17*(1+'Input Fee and Elasticity Inputs'!$B$12)))) -> 164399.4 | Y17: =F17*V17 -> 4.11 | Z17: =Y17*X17 -> 675681.53 | AA17: =Z17-U17 -> -35562.186
A18: Papa John's | B18: 170448 | C18: 43 | D18: 74 | E18: 0.49 | F18: 21.6 | G18: 0.3 | H18: 0.09 | I18: 0.023684085 | J18: 25 | K18: =if(C18>20,"Enterprise","SMB") -> Enterprise | L18: =F18*G18 -> 6.48 | M18: =PERCENTRANK(B$2:B$201,B18)*'Input Resturant Brands Scoring '!$B$3 -> 32.2 | N18: =(1-PERCENTRANK(J$2:J$201,J18))*'Input Resturant Brands Scoring '!$B$5 -> 2.358 | O18: =(1-PERCENTRANK(I$2:I$201,I18))*'Input Resturant Brands Scoring '!$B$6 -> 3.252 | P18: =sum(N18:O18) -> 5.61 | Q18: =PERCENTRANK(L$2:L$201,L18)*'Input Resturant Brands Scoring '!$B$7 -> 25.515 | R18: =M18+N18+O18+Q18 -> 63.325 | S18: =RANK(R18,R$2:R$201,0) -> 43 | T18: =IF(S18<=10,"S",IF(S18<=50,"A",IF(S18<=150,"B","C"))) -> A | U18: =G18*F18*B18 -> 1104503 | V18: =MIN(0.3, MAX(0.1, IF(T18="S", G18-0.02, IF(T18="A", G18-0.005, IF(T18="B", G18+0.02, G18+0.03))))) -> 0.295 | W18: =V18-G18 -> -0.005 | X18: =IF(T18="S", B18*(1+'Input Fee and Elasticity Inputs'!$B$9), IF(T18="A", B18*(1+'Input Fee and Elasticity Inputs'!$B$10), IF(T18="B", B18*(1+'Input Fee and Elasticity Inputs'!$B$11), B18*(1+'Input Fee and Elasticity Inputs'!$B$12)))) -> 187492.8 | Y18: =F18*V18 -> 6.372 | Z18: =Y18*X18 -> 1194704.1 | AA18: =Z18-U18 -> 90201.082
